{
 "cells": [
  {
   "cell_type": "code",
   "execution_count": 1,
   "metadata": {},
   "outputs": [],
   "source": [
    "import numpy as np"
   ]
  },
  {
   "cell_type": "code",
   "execution_count": 7,
   "metadata": {},
   "outputs": [],
   "source": [
    "random_matrix = np.random.randint(0, high=65520, size=(6, 8))"
   ]
  },
  {
   "cell_type": "code",
   "execution_count": 8,
   "metadata": {},
   "outputs": [
    {
     "data": {
      "text/plain": [
       "array([[55760, 36739,  6521, 12682, 14951, 21558,   195, 28800],\n",
       "       [ 1424, 22822, 57160, 52376, 40871, 23289, 41225, 60434],\n",
       "       [ 8233, 41301, 29337, 22663, 46259, 57432,  2571, 11508],\n",
       "       [10105,  9411, 62265, 23137, 12822, 42198, 61292,  6441],\n",
       "       [61606, 34669, 12785,  9754, 39887, 58241, 37791,  1475],\n",
       "       [60379,  1722, 54370, 55726, 61946, 51736, 18868, 54864]])"
      ]
     },
     "execution_count": 8,
     "metadata": {},
     "output_type": "execute_result"
    }
   ],
   "source": [
    "random_matrix"
   ]
  },
  {
   "cell_type": "code",
   "execution_count": 11,
   "metadata": {},
   "outputs": [],
   "source": [
    "mod = 65521"
   ]
  },
  {
   "cell_type": "code",
   "execution_count": 12,
   "metadata": {},
   "outputs": [
    {
     "data": {
      "text/plain": [
       "224"
      ]
     },
     "execution_count": 12,
     "metadata": {},
     "output_type": "execute_result"
    }
   ],
   "source": [
    "224 % mod"
   ]
  },
  {
   "cell_type": "code",
   "execution_count": 13,
   "metadata": {},
   "outputs": [],
   "source": [
    "from sympy import *"
   ]
  },
  {
   "cell_type": "code",
   "execution_count": 15,
   "metadata": {},
   "outputs": [
    {
     "name": "stderr",
     "output_type": "stream",
     "text": [
      "ERROR:root:Internal Python error in the inspect module.\n",
      "Below is the traceback from this internal error.\n",
      "\n"
     ]
    },
    {
     "name": "stdout",
     "output_type": "stream",
     "text": [
      "Traceback (most recent call last):\n",
      "  File \"/Users/brad/anaconda3/lib/python3.7/site-packages/IPython/core/interactiveshell.py\", line 3267, in run_code\n",
      "    exec(code_obj, self.user_global_ns, self.user_ns)\n",
      "  File \"<ipython-input-15-ce86d833987b>\", line 1, in <module>\n",
      "    from sympy import mul_inverse\n",
      "ImportError: cannot import name 'mul_inverse' from 'sympy' (/Users/brad/anaconda3/lib/python3.7/site-packages/sympy/__init__.py)\n",
      "\n",
      "During handling of the above exception, another exception occurred:\n",
      "\n",
      "Traceback (most recent call last):\n",
      "  File \"/Users/brad/anaconda3/lib/python3.7/site-packages/IPython/core/interactiveshell.py\", line 2018, in showtraceback\n",
      "    stb = value._render_traceback_()\n",
      "AttributeError: 'ImportError' object has no attribute '_render_traceback_'\n",
      "\n",
      "During handling of the above exception, another exception occurred:\n",
      "\n",
      "Traceback (most recent call last):\n",
      "  File \"/Users/brad/anaconda3/lib/python3.7/site-packages/IPython/core/ultratb.py\", line 1095, in get_records\n",
      "    return _fixed_getinnerframes(etb, number_of_lines_of_context, tb_offset)\n",
      "  File \"/Users/brad/anaconda3/lib/python3.7/site-packages/IPython/core/ultratb.py\", line 313, in wrapped\n",
      "    return f(*args, **kwargs)\n",
      "  File \"/Users/brad/anaconda3/lib/python3.7/site-packages/IPython/core/ultratb.py\", line 347, in _fixed_getinnerframes\n",
      "    records = fix_frame_records_filenames(inspect.getinnerframes(etb, context))\n",
      "  File \"/Users/brad/anaconda3/lib/python3.7/inspect.py\", line 1502, in getinnerframes\n",
      "    frameinfo = (tb.tb_frame,) + getframeinfo(tb, context)\n",
      "  File \"/Users/brad/anaconda3/lib/python3.7/inspect.py\", line 1460, in getframeinfo\n",
      "    filename = getsourcefile(frame) or getfile(frame)\n",
      "  File \"/Users/brad/anaconda3/lib/python3.7/inspect.py\", line 696, in getsourcefile\n",
      "    if getattr(getmodule(object, filename), '__loader__', None) is not None:\n",
      "  File \"/Users/brad/anaconda3/lib/python3.7/inspect.py\", line 725, in getmodule\n",
      "    file = getabsfile(object, _filename)\n",
      "  File \"/Users/brad/anaconda3/lib/python3.7/inspect.py\", line 709, in getabsfile\n",
      "    return os.path.normcase(os.path.abspath(_filename))\n",
      "  File \"/Users/brad/anaconda3/lib/python3.7/posixpath.py\", line 383, in abspath\n",
      "    cwd = os.getcwd()\n",
      "FileNotFoundError: [Errno 2] No such file or directory\n"
     ]
    },
    {
     "ename": "ImportError",
     "evalue": "cannot import name 'mul_inverse' from 'sympy' (/Users/brad/anaconda3/lib/python3.7/site-packages/sympy/__init__.py)",
     "output_type": "error",
     "traceback": [
      "\u001b[0;31m---------------------------------------------------------------------------\u001b[0m"
     ]
    }
   ],
   "source": [
    "from sympy import mul_inverse"
   ]
  },
  {
   "cell_type": "code",
   "execution_count": null,
   "metadata": {},
   "outputs": [],
   "source": []
  }
 ],
 "metadata": {
  "kernelspec": {
   "display_name": "Python 3",
   "language": "python",
   "name": "python3"
  },
  "language_info": {
   "codemirror_mode": {
    "name": "ipython",
    "version": 3
   },
   "file_extension": ".py",
   "mimetype": "text/x-python",
   "name": "python",
   "nbconvert_exporter": "python",
   "pygments_lexer": "ipython3",
   "version": "3.7.2"
  }
 },
 "nbformat": 4,
 "nbformat_minor": 2
}
